Workbook

Sheet Исходные данные
A1: Наименование показателя | B1: D, м | C1: H,м | D1: n | E1: L, м | F1: Масса, т | G1: % | H1: Масса, т | L1: данные, которые вводим самостоятельно
A2: Количество коз-у в комплекте | D2: 1
A3: Высота стенки КОЗ-У-Ш | C3: 0.017
A4: Нижнее опорное кольцо | B4: 0.015
A5: Верхнее наружное кольцо | B5: 0.019
A6: Верхнее внутреннее кольцо | B6: =B5-1.4 -> -1.381
A7: Сетка "Манье"
A8: Тросы горизонтальные | D8: =ROUND(((C3-2.5)/1),0)-1 -> -3
A9: Тросы вертикальные | D9: =ROUND((B5/0.5),0)*2-15 -> -15 | E9: =B5+(C3-2.5)*2 -> -4.947
A10: Общая масса конструкции по модели | F10: 15.2
A11: Монтаж нижнего опорного кольца и конструкций антисдвига СК-2 | G11: 9.07 | H11: =F10*0.0907 -> 1.37864
A12: Монтаж стоек (ног) и креплений | G12: 60.82 | H12: =F10*0.6082 -> 9.24464
A13: Устройство промежуточных колец и креплений | G13: 12.07 | H13: =F10*0.1207 -> 1.83464
A14: Монтаж внутреннего и внешнего верхних наружных колец и раскосов | G14: 14.87 | H14: =F10*0.1487 -> 2.26024
A15: Устройство распорного кольца и упоров | G15: 3.17 | H15: =F10*0.0317 -> 0.48184
A16: Болты | D16: =12796.03*H16 -> 13673.326 | G16: 7.03 | H16: =F10*0.0703 -> 1.06856
A17: Зажим | D17: =D9*2 -> -30
A18: Система сброса | D18: =ROUND(((B5*3.14)/2),0) -> 0
A19: Кол-во контуров заземления | D19: 1
A20: Длина луча заземления | E20: 50

Sheet ВОР без габиона
A1: Перечень рабочих операций и объемы работ к калькуляции затрат строительных ресурсов
A2: Устройство защитной конструкции РВС-1000 КОЗ-У-Ш, 1 шт.
A3: № п/п | B3: Перечень рабочих операций | C3: Ед. изм. | D3: Подсчет объемов работ | G3: Ссылка на номера чертежей, ГОСТов и примечания
D4: Кол-во на 1 КОЗ-У-Ш | E4: Кол-во на комплект | F4: Формула подсчета
A5: 1 | B5: 2 | C5: 3 | D5: 4 | E5: 5 | F5: 6 | G5: 7
A6: Раздел 1. Подготовительные работы
A7: 1 | B7: Установка наружных инвентарных лесов | C7: 100 м2 | D7: =(3.14*('Исходные данные'!B4/2+'Исходные данные'!B5/2)*'Исходные данные'!C3)*1.5/100 -> 1.36119e-05 | E7: =D7*'Исходные данные'!D2 -> 1.36119e-05 | F7: Площадь вертикальной проекции на фасад конструкции Sбок = π(R1+R2)хH | G7: ГЭСН 08-07-001-02
B8: Материалы:
B9: Детали деревянные лесов из пиломатериалов хвойных пород | C9: м3 | D9: =0.009*D7 -> 1.225071e-07 | E9: =D9*'Исходные данные'!D2 -> 1.225071e-07
B10: Детали стальных трубчатых лесов, укомплектованные пробками, крючками и хомутами, окрашенные | C10: т | D10: =0.035*D7 -> 4.764165e-07 | E10: =D10*'Исходные данные'!D2 -> 4.764165e-07
B11: Щиты настила | C11: м2 | D11: =3.4*D7 -> 4.628046e-05 | E11: =D11*'Исходные данные'!D2 -> 4.628046e-05
B12: Машины и механизмы:
B13: Автомобили бортовые, грузоподъемность до 5 т
A14: Раздел 2. Устройство подготовки под конструкцию
A15: 1 | B15: Укладка резиновых прокладок толщиной: 30 мм | C15: 100 м2 площади прокладок | D15: =1.2/100 -> 0.012 | E15: =D15*'Исходные данные'!D2 -> 0.012 | F15: Sпрокладок = n х S | G15: ГЭСН 07-01-060-01
B16: Материалы:
B17: Прокладки резиновые (пластина техническая прессованная) | C17: шт. | D17: 20 | E17: =D17*'Исходные данные'!D2 -> 20
B18: Машины и механизмы:
B19: Автомобили бортовые, грузоподъемность до 5 т
A20: 2 | B20: Укладка металлических пластин | C20: 1 т конструкций | D20: =9.42/1000 -> 0.00942 | E20: =D20*'Исходные данные'!D2 -> 0.00942 | F20: Sпластин = n х S | G20: ГЭСН 09-03-001-01
B21: Материалы:
B22: Пластины металлические, толщиной 10 мм, длиной 300 мм, шириной 200 мм | C22: шт. | D22: 20 | E22: =D22*'Исходные данные'!D2 -> 20
B23: Машины и механизмы:
B24: Автомобили бортовые, грузоподъемность до 5 т
A25: 3 | B25: Установка стабилизатора гашения ветровой и ударной нагрузки на фундамент | C25: 1 т металлической констррукции | D25: =1.8*7.85/1000 -> 0.01413 | E25: =D25*'Исходные данные'!$D$2 -> 0.01413
B26: Материалы:
B27: Конструкции стальные | C27: 1 т | D27: =D25 -> 0.01413 | E27: =E25 -> 0.01413
B28: Машины и механизмы:
B29: Краны на автомобильном ходу при работе на других видах строительства 10 т
B30: Подъемники гидравлические высотой подъема 20 м
B31: Автомобили бортовые, грузоподъемность до 5 т
B32: Лебедки тракторные тяговым усилием 2,5 т
A33: Раздел 3. Монтаж металлоконструкций КОЗ - У - Ш
A34: 1 | B34: Монтаж нижнего опорного кольца и конструкций опоры в составе антисдвига 4-го типа | C34: 1 т металлической констррукции | D34: ='Исходные данные'!H11 -> 1.37864 | E34: =D34*'Исходные данные'!$D$2 -> 1.37864 | F34: M = n х m, где n - количество элементов, m - масса элемента
B35: Материалы:
B36: Конструкции стальные | C36: 1 т | D36: =D34 -> 1.37864 | E36: =D36*'Исходные данные'!$D$2 -> 1.37864
B37: Машины и механизмы:
B38: Краны на автомобильном ходу при работе на других видах строительства 10 т
B39: Подъемники гидравлические высотой подъема 20 м
B40: Автомобили бортовые, грузоподъемность до 5 т
...

Sheet ВОР с габионом
A1: Перечень рабочих операций и объемы работ к калькуляции затрат строительных ресурсов
A2: Устройство защитной конструкции РВС-1000 КОЗ-У-Ш, 1 шт.
A3: № п/п | B3: Перечень рабочих операций | C3: Ед. изм. | D3: Подсчет объемов работ | G3: Ссылка на номера чертежей, ГОСТов и примечания
D4: Кол-во на 1 КОЗ-У-Ш | E4: Кол-во на комплект | F4: Формула подсчета
A5: 1 | B5: 2 | C5: 3 | D5: 4 | E5: 5 | F5: 6 | G5: 7
A6: Раздел 1. Подготовительные работы
A7: 1 | B7: Установка наружных инвентарных лесов | C7: 100 м2 | D7: =(3.14*('Исходные данные'!B4/2+'Исходные данные'!B5/2)*'Исходные данные'!C3)*1.5/100 -> 1.36119e-05 | E7: =D7*'Исходные данные'!D2 -> 1.36119e-05 | F7: Площадь вертикальной проекции на фасад конструкции Sбок = π(R1+R2)хH | G7: ГЭСН 08-07-001-02
B8: Материалы:
B9: Детали деревянные лесов из пиломатериалов хвойных пород | C9: м3 | D9: =0.009*D7 -> 1.225071e-07 | E9: =D9*'Исходные данные'!D2 -> 1.225071e-07
B10: Детали стальных трубчатых лесов, укомплектованные пробками, крючками и хомутами, окрашенные | C10: т | D10: =0.035*D7 -> 4.764165e-07 | E10: =D10*'Исходные данные'!D2 -> 4.764165e-07
B11: Щиты настила | C11: м2 | D11: =3.4*D7 -> 4.628046e-05 | E11: =D11*'Исходные данные'!D2 -> 4.628046e-05
B12: Машины и механизмы:
B13: Автомобили бортовые, грузоподъемность до 5 т
A14: Раздел 2. Земляные работы
A15: 1 | B15: Разработка грунта с погрузкой на автомобили-самосвалы экскаваторами с ковшом вместимостью: 2,5 (1,5-3) м3, группа грунтов 1 * | C15: 1000 м3 | D15: =(3.14*((('Исходные данные'!B4+2)/2)^2-(('Исходные данные'!B4-2)/2)^2))*1/1000 -> 9.42e-05 | E15: =D15*'Исходные данные'!D2 -> 9.42e-05 | F15: S = πх(R^2-r^2), V = S х h | G15: ГЭСН 01-01-012-01
B16: Машины и механизмы:
B17: Экскаваторы одноковшовые электрические на гусеничном ходу при работе на других видах строительства 2,5 м3
B18: Бульдозеры при работе на других видах строительства 79 кВт (108 л.с.)
B19: Материалы:
B20: Щебень | C20: м3 | D20: =0.02*D15 -> 1.884e-06 | E20: =D20*'Исходные данные'!D2 -> 1.884e-06
A21: 2 | B21: Снятие растительного слоя с перемещением до 10 м бульдозерами мощностью: 96 кВт (130 л.с.), группа грунтов 1* | C21: 1000 м3 | D21: =(3.14*((('Исходные данные'!B4+2)/2)^2-(('Исходные данные'!B4-2)/2)^2))*0.15/1000 -> 1.413e-05 | E21: =D21*'Исходные данные'!D2 -> 1.413e-05 | F21: Sсрез = πх(R^2-r^2), Vсрез = Sсрез х hраст.слоя. | G21: ГЭСН 01-01-031-01
B22: Машины и механизмы:
B23: Бульдозеры при работе на других видах строительства 96 кВт (130 л.с.)
A24: 3 | B24: Вывоз грунта со строительной площадки* | C24: 1000 м3 | D24: =D21+D15 -> 0.00010833 | E24: =D24*'Исходные данные'!D2 -> 0.00010833 | G24: ТСН-2001.15-1
B25: Машины и механизмы:
B26: Автомобили бортовые, грузоподъемность до 5 т
A27: 4 | B27: Устройство основания под фундаменты: песчаного* | C27: 1 м3 основания | D27: =(3.14*((('Исходные данные'!B4+1)/2)^2-(('Исходные данные'!B4-1)/2)^2))*0.2 -> 0.00942 | E27: =D27*'Исходные данные'!D2 -> 0.00942 | F27: Sпес. = πх(R^2-r^2), Vпес. = Sпес. х hпес. | G27: ГЭСН 08-01-002-01
B28: Материалы:
B29: Песок для строительных работ природный | C29: м3 | D29: =D27*1.2 -> 0.011304 | E29: =D29*'Исходные данные'!D2 -> 0.011304
B30: Вода | C30: м3 | D30: =D27*0.15 -> 0.001413 | E30: =D30*'Исходные данные'!D2 -> 0.001413
B31: Машины и механизмы:
B32: Погрузчики одноковшовые универсальные фронтальные пневмоколесные 3 т
B33: Компрессоры передвижные с двигателем внутреннего сгорания давлением до 686 кПа (7 ат), производительность 2,2 м3/мин
B34: Трамбовки пневматические при работе от передвижных компрессорных станций
A35: 5 | B35: Уплотнение вибротрамбовкой* | C35: 100 м3 | D35: =D27/100 -> 9.42e-05 | E35: =D35*'Исходные данные'!D2 -> 9.42e-05 | F35: S = πх(R^2-r^2), V = S х h | G35: ГЭСН 01-02-014-01
B36: Машины и механизмы:
B37: Вибротрамбовки бензиновые, мощность до 4 кВт
A38: 6 | B38: Устройство прослойки из негорючего геотекстиля* | C38: 1000 м2 | D38: =(3.14*((('Исходные данные'!B4+1)/2)^2-(('Исходные данные'!B4-2)/2)^1))/1000 -> 0.0039251766 | E38: =D38*'Исходные данные'!D2 -> 0.0039251766 | F38: S = πх(R^2-r^2) | G38: ГЭСН 27-04-016-04
B39: Материалы:
B40: Поковки из квадратных заготовок, масса 1,8 кг | C40: т | D40: =0.00013*D38 -> 5.1027296e-07 | E40: =D40*'Исходные данные'!D2 -> 5.1027296e-07
...
